Workbook

Sheet Chain
A1: =A2+1 -> 400 | B1: 5 | C1: 1 | E1: =SUM(D1:D120) -> 1.4028367e+25 | F1: =SUM(Feeder!A1:A20) -> 15620
A2: =A3+1 -> 399 | B2: =B1+2 -> 7 | C2: 1
A3: =A4+1 -> 398 | B3: =B2+2 -> 9 | C3: =SUM(C1:C2) -> 2
A4: =A5+1 -> 397 | B4: =B3+2 -> 11 | C4: =SUM(C2:C3) -> 3
A5: =A6+1 -> 396 | B5: =B4+2 -> 13 | C5: =SUM(C3:C4) -> 5
A6: =A7+1 -> 395 | B6: =B5+2 -> 15 | C6: =SUM(C4:C5) -> 8
A7: =A8+1 -> 394 | B7: =B6+2 -> 17 | C7: =SUM(C5:C6) -> 13
A8: =A9+1 -> 393 | B8: =B7+2 -> 19 | C8: =SUM(C6:C7) -> 21
A9: =A10+1 -> 392 | B9: =B8+2 -> 21 | C9: =SUM(C7:C8) -> 34
A10: =A11+1 -> 391 | B10: =B9+2 -> 23 | C10: =SUM(C8:C9) -> 55 | D10: =SUM(C1:C10) -> 143
A11: =A12+1 -> 390 | B11: =B10+2 -> 25 | C11: =SUM(C9:C10) -> 89
A12: =A13+1 -> 389 | B12: =B11+2 -> 27 | C12: =SUM(C10:C11) -> 144
A13: =A14+1 -> 388 | B13: =B12+2 -> 29 | C13: =SUM(C11:C12) -> 233
A14: =A15+1 -> 387 | B14: =B13+2 -> 31 | C14: =SUM(C12:C13) -> 377
A15: =A16+1 -> 386 | B15: =B14+2 -> 33 | C15: =SUM(C13:C14) -> 610
A16: =A17+1 -> 385 | B16: =B15+2 -> 35 | C16: =SUM(C14:C15) -> 987
A17: =A18+1 -> 384 | B17: =B16+2 -> 37 | C17: =SUM(C15:C16) -> 1597
A18: =A19+1 -> 383 | B18: =B17+2 -> 39 | C18: =SUM(C16:C17) -> 2584
A19: =A20+1 -> 382 | B19: =B18+2 -> 41 | C19: =SUM(C17:C18) -> 4181
A20: =A21+1 -> 381 | B20: =B19+2 -> 43 | C20: =SUM(C18:C19) -> 6765 | D20: =SUM(C11:C20) -> 17567
A21: =A22+1 -> 380 | B21: =B20+2 -> 45 | C21: =SUM(C19:C20) -> 10946
A22: =A23+1 -> 379 | B22: =B21+2 -> 47 | C22: =SUM(C20:C21) -> 17711
A23: =A24+1 -> 378 | B23: =B22+2 -> 49 | C23: =SUM(C21:C22) -> 28657
A24: =A25+1 -> 377 | B24: =B23+2 -> 51 | C24: =SUM(C22:C23) -> 46368
A25: =A26+1 -> 376 | B25: =B24+2 -> 53 | C25: =SUM(C23:C24) -> 75025
A26: =A27+1 -> 375 | B26: =B25+2 -> 55 | C26: =SUM(C24:C25) -> 121393
A27: =A28+1 -> 374 | B27: =B26+2 -> 57 | C27: =SUM(C25:C26) -> 196418
A28: =A29+1 -> 373 | B28: =B27+2 -> 59 | C28: =SUM(C26:C27) -> 317811
A29: =A30+1 -> 372 | B29: =B28+2 -> 61 | C29: =SUM(C27:C28) -> 514229
A30: =A31+1 -> 371 | B30: =B29+2 -> 63 | C30: =SUM(C28:C29) -> 832040 | D30: =SUM(C21:C30) -> 2160598
A31: =A32+1 -> 370 | B31: =B30+2 -> 65 | C31: =SUM(C29:C30) -> 1346269
A32: =A33+1 -> 369 | B32: =B31+2 -> 67 | C32: =SUM(C30:C31) -> 2178309
A33: =A34+1 -> 368 | B33: =B32+2 -> 69 | C33: =SUM(C31:C32) -> 3524578
A34: =A35+1 -> 367 | B34: =B33+2 -> 71 | C34: =SUM(C32:C33) -> 5702887
A35: =A36+1 -> 366 | B35: =B34+2 -> 73 | C35: =SUM(C33:C34) -> 9227465
A36: =A37+1 -> 365 | B36: =B35+2 -> 75 | C36: =SUM(C34:C35) -> 14930352
A37: =A38+1 -> 364 | B37: =B36+2 -> 77 | C37: =SUM(C35:C36) -> 24157817
A38: =A39+1 -> 363 | B38: =B37+2 -> 79 | C38: =SUM(C36:C37) -> 39088169
A39: =A40+1 -> 362 | B39: =B38+2 -> 81 | C39: =SUM(C37:C38) -> 63245986
A40: =A41+1 -> 361 | B40: =B39+2 -> 83 | C40: =SUM(C38:C39) -> 102334155 | D40: =SUM(C31:C40) -> 265735987
...

Sheet Feeder
A1: =Chain!A1*2 -> 800
A2: =Chain!A2*2 -> 798
A3: =Chain!A3*2 -> 796
A4: =Chain!A4*2 -> 794
A5: =Chain!A5*2 -> 792
A6: =Chain!A6*2 -> 790
A7: =Chain!A7*2 -> 788
A8: =Chain!A8*2 -> 786
A9: =Chain!A9*2 -> 784
A10: =Chain!A10*2 -> 782
A11: =Chain!A11*2 -> 780
A12: =Chain!A12*2 -> 778
... A20: =Chain!A20*2 -> 762
